[W 13:14:10.994 NotebookApp] Loading JupyterLab as a classic notebook (v6) extension.
[I 2023-03-15 13:14:10.997 LabApp] JupyterLab extension loaded from /home/gang/anaconda3/envs/ETRI/lib/python3.9/site-packages/jupyterlab
[I 2023-03-15 13:14:10.997 LabApp] JupyterLab application directory is /home/gang/anaconda3/envs/ETRI/share/jupyter/lab
[I 13:14:11.479 NotebookApp] The port 8888 is already in use, trying another port.
[I 13:14:11.479 NotebookApp] Serving notebooks from local directory: /home/gang/PycharmProjects/ETRI2023
[I 13:14:11.479 NotebookApp] Jupyter Notebook 6.5.2 is running at:
[I 13:14:11.479 NotebookApp] http://localhost:8889/?token=e62bc816a9903af470f1076f6ba37f28fda3726dd87d17a6
[I 13:14:11.480 NotebookApp]  or http://127.0.0.1:8889/?token=e62bc816a9903af470f1076f6ba37f28fda3726dd87d17a6
[I 13:14:11.480 NotebookApp] Use Control-C to stop this server and shut down all kernels (twice to skip confirmation).
[C 13:14:11.496 NotebookApp] 
    
    To access the notebook, open this file in a browser:
        file:///home/gang/.local/share/jupyter/runtime/nbserver-528381-open.html
    Or copy and paste one of these URLs:
        http://localhost:8889/?token=e62bc816a9903af470f1076f6ba37f28fda3726dd87d17a6
     or http://127.0.0.1:8889/?token=e62bc816a9903af470f1076f6ba37f28fda3726dd87d17a6
[W 19:01:21.187 NotebookApp] Notebook EDA_gang.ipynb is not trusted
[I 19:01:21.690 NotebookApp] Kernel started: e3ec7cab-9504-4067-b4ee-5dac587908b8, name: python3
[I 19:03:21.709 NotebookApp] Saving file at /EDA_gang.ipynb
[I 19:05:21.705 NotebookApp] Saving file at /EDA_gang.ipynb
[I 19:07:21.721 NotebookApp] Saving file at /EDA_gang.ipynb
[I 19:11:21.725 NotebookApp] Saving file at /EDA_gang.ipynb
[I 19:13:21.719 NotebookApp] Saving file at /EDA_gang.ipynb
[I 19:15:21.724 NotebookApp] Saving file at /EDA_gang.ipynb
[I 19:17:21.717 NotebookApp] Saving file at /EDA_gang.ipynb
[I 19:19:21.729 NotebookApp] Saving file at /EDA_gang.ipynb
/home/gang/anaconda3/envs/ETRI/lib/python3.9/site-packages/nbformat/__init__.py:128: MissingIDFieldWarning: Code cell is missing an id field, this will become a hard error in future nbformat versions. You may want to use `normalize()` on your notebooks before validations (available since nbformat 5.1.4). Previous versions of nbformat are fixing this issue transparently, and will stop doing so in the future.
  validate(nb)
/home/gang/anaconda3/envs/ETRI/lib/python3.9/site-packages/notebook/services/contents/manager.py:353: MissingIDFieldWarning: Code cell is missing an id field, this will become a hard error in future nbformat versions. You may want to use `normalize()` on your notebooks before validations (available since nbformat 5.1.4). Previous versions of nbformat are fixing this issue transparently, and will stop doing so in the future.
  validate_nb(model['content'])
[I 19:21:22.419 NotebookApp] Saving file at /EDA_gang.ipynb
[I 19:22:06.495 NotebookApp] Kernel interrupted: e3ec7cab-9504-4067-b4ee-5dac587908b8
[I 19:23:00.889 NotebookApp] Saving file at /EDA_gang.ipynb
[I 19:23:21.975 NotebookApp] Saving file at /EDA_gang.ipynb
[I 19:24:03.065 NotebookApp] Kernel interrupted: e3ec7cab-9504-4067-b4ee-5dac587908b8
[I 19:25:22.475 NotebookApp] Saving file at /EDA_gang.ipynb
[I 19:27:22.612 NotebookApp] Saving file at /EDA_gang.ipynb
[I 19:29:22.602 NotebookApp] Saving file at /EDA_gang.ipynb
[I 19:30:12.692 NotebookApp] Saving file at /EDA_gang.ipynb
[I 19:33:22.599 NotebookApp] Saving file at /EDA_gang.ipynb
[C 21:27:14.252 NotebookApp] received signal 15, stopping
[I 21:27:14.252 NotebookApp] Shutting down 1 kernel
[I 21:27:14.253 NotebookApp] Kernel shutdown: e3ec7cab-9504-4067-b4ee-5dac587908b8
[I 21:27:14.316 NotebookApp] Starting buffering for e3ec7cab-9504-4067-b4ee-5dac587908b8:5951a97544084b96bdaddb8e2e845aa2
[I 21:27:14.319 NotebookApp] Kernel shutdown: e3ec7cab-9504-4067-b4ee-5dac587908b8
[E 21:27:14.319 NotebookApp] Uncaught exception DELETE /api/sessions/47b6bfbf-3e88-45e3-8506-1dbd0cdd33c2 (127.0.0.1)
    HTTPServerRequest(protocol='http', host='localhost:8889', method='DELETE', uri='/api/sessions/47b6bfbf-3e88-45e3-8506-1dbd0cdd33c2', version='HTTP/1.1', remote_ip='127.0.0.1')
    Traceback (most recent call last):
      File "/home/gang/anaconda3/envs/ETRI/lib/python3.9/site-packages/tornado/web.py", line 1713, in _execute
        result = await result
      File "/home/gang/anaconda3/envs/ETRI/lib/python3.9/site-packages/tornado/gen.py", line 776, in run
        yielded = self.gen.throw(*exc_info)  # type: ignore
      File "/home/gang/anaconda3/envs/ETRI/lib/python3.9/site-packages/notebook/services/sessions/handlers.py", line 164, in delete
        yield maybe_future(sm.delete_session(session_id))
      File "/home/gang/anaconda3/envs/ETRI/lib/python3.9/site-packages/tornado/gen.py", line 769, in run
        value = future.result()
      File "/home/gang/anaconda3/envs/ETRI/lib/python3.9/site-packages/tornado/gen.py", line 782, in run
        yielded = self.gen.send(value)
      File "/home/gang/anaconda3/envs/ETRI/lib/python3.9/site-packages/notebook/services/sessions/sessionmanager.py", line 287, in delete_session
        yield maybe_future(self.kernel_manager.shutdown_kernel(session['kernel']['id']))
      File "/home/gang/anaconda3/envs/ETRI/lib/python3.9/site-packages/notebook/services/kernels/kernelmanager.py", line 304, in shutdown_kernel
        self.pinned_superclass.shutdown_kernel(self, kernel_id, now=now, restart=restart)
      File "/home/gang/anaconda3/envs/ETRI/lib/python3.9/site-packages/jupyter_client/utils.py", line 30, in wrapped
        raise e
      File "/home/gang/anaconda3/envs/ETRI/lib/python3.9/site-packages/jupyter_client/utils.py", line 27, in wrapped
        return loop.run_until_complete(future)
      File "/home/gang/anaconda3/envs/ETRI/lib/python3.9/site-packages/nest_asyncio.py", line 90, in run_until_complete
        return f.result()
      File "/home/gang/anaconda3/envs/ETRI/lib/python3.9/asyncio/futures.py", line 201, in result
        raise self._exception
      File "/home/gang/anaconda3/envs/ETRI/lib/python3.9/asyncio/tasks.py", line 256, in __step
        result = coro.send(None)
      File "/home/gang/anaconda3/envs/ETRI/lib/python3.9/site-packages/jupyter_client/multikernelmanager.py", line 264, in _async_shutdown_kernel
        if not km.ready.cancelled() and km.ready.exception():
    asyncio.exceptions.InvalidStateError: Exception is not set.
[W 21:27:14.320 NotebookApp] Unhandled error
[E 21:27:14.320 NotebookApp] {
      "Host": "localhost:8889",
      "Accept": "application/json, text/javascript, */*; q=0.01",
      "Referer": "http://localhost:8889/notebooks/EDA_gang.ipynb",
      "User-Agent": "Mozilla/5.0 (X11; Linux x86_64) AppleWebKit/537.36 (KHTML, like Gecko) Chrome/110.0.0.0 Safari/537.36"
    }
[E 21:27:14.320 NotebookApp] 500 DELETE /api/sessions/47b6bfbf-3e88-45e3-8506-1dbd0cdd33c2 (127.0.0.1) 1.980000ms referer=http://localhost:8889/notebooks/EDA_gang.ipynb
[I 21:27:14.867 NotebookApp] Shutting down 0 terminals
[W 16:21:55.143 NotebookApp] Loading JupyterLab as a classic notebook (v6) extension.
[I 2023-03-18 16:21:55.146 LabApp] JupyterLab extension loaded from /home/gang/anaconda3/envs/ETRI/lib/python3.9/site-packages/jupyterlab
[I 2023-03-18 16:21:55.146 LabApp] JupyterLab application directory is /home/gang/anaconda3/envs/ETRI/share/jupyter/lab
[I 16:21:55.628 NotebookApp] Serving notebooks from local directory: /home/gang/PycharmProjects/ETRI2023
[I 16:21:55.628 NotebookApp] Jupyter Notebook 6.5.2 is running at:
[I 16:21:55.628 NotebookApp] http://localhost:8888/?token=2a07dedac408f76588a303aab1b6df983701c81f7d85595a
[I 16:21:55.628 NotebookApp]  or http://127.0.0.1:8888/?token=2a07dedac408f76588a303aab1b6df983701c81f7d85595a
[I 16:21:55.628 NotebookApp] Use Control-C to stop this server and shut down all kernels (twice to skip confirmation).
[C 16:21:55.643 NotebookApp] 
    
    To access the notebook, open this file in a browser:
        file:///home/gang/.local/share/jupyter/runtime/nbserver-676504-open.html
    Or copy and paste one of these URLs:
        http://localhost:8888/?token=2a07dedac408f76588a303aab1b6df983701c81f7d85595a
     or http://127.0.0.1:8888/?token=2a07dedac408f76588a303aab1b6df983701c81f7d85595a
[W 16:22:02.505 NotebookApp] Notebook EDA_gang.ipynb is not trusted
[I 16:22:04.014 NotebookApp] Kernel started: aeceefd9-a79b-475e-805a-ae88dfaec4bd, name: python3
[W 16:22:18.531 NotebookApp] 404 GET /api/contents/EDA-Python/006-Housing-Prices?type=directory&_=1678071800322 (127.0.0.1): file or directory does not exist: 'EDA-Python/006-Housing-Prices'
[W 16:22:18.531 NotebookApp] file or directory does not exist: 'EDA-Python/006-Housing-Prices'
[W 16:22:18.531 NotebookApp] 404 GET /api/contents/EDA-Python/006-Housing-Prices?type=directory&_=1678071800322 (127.0.0.1) 1.150000ms referer=http://localhost:8888/tree/EDA-Python/006-Housing-Prices
[I 16:25:35.355 NotebookApp] Creating new notebook in 
[I 16:25:35.974 NotebookApp] Kernel started: b08c12d5-ff07-455f-8929-273f93c7ca68, name: python3
[I 16:27:35.968 NotebookApp] Saving file at /Untitled.ipynb
/home/gang/anaconda3/envs/ETRI/lib/python3.9/site-packages/nbformat/__init__.py:128: MissingIDFieldWarning: Code cell is missing an id field, this will become a hard error in future nbformat versions. You may want to use `normalize()` on your notebooks before validations (available since nbformat 5.1.4). Previous versions of nbformat are fixing this issue transparently, and will stop doing so in the future.
  validate(nb)
/home/gang/anaconda3/envs/ETRI/lib/python3.9/site-packages/notebook/services/contents/manager.py:353: MissingIDFieldWarning: Code cell is missing an id field, this will become a hard error in future nbformat versions. You may want to use `normalize()` on your notebooks before validations (available since nbformat 5.1.4). Previous versions of nbformat are fixing this issue transparently, and will stop doing so in the future.
  validate_nb(model['content'])
[I 16:29:35.967 NotebookApp] Saving file at /Untitled.ipynb
[I 16:31:35.959 NotebookApp] Saving file at /Untitled.ipynb
[I 16:33:35.959 NotebookApp] Saving file at /Untitled.ipynb
[I 16:35:35.968 NotebookApp] Saving file at /Untitled.ipynb
[I 16:37:35.959 NotebookApp] Saving file at /Untitled.ipynb
[C 17:45:38.857 NotebookApp] received signal 15, stopping
[I 17:45:38.858 NotebookApp] Shutting down 2 kernels
[I 17:45:38.858 NotebookApp] Kernel shutdown: b08c12d5-ff07-455f-8929-273f93c7ca68
[I 17:45:38.914 NotebookApp] Starting buffering for b08c12d5-ff07-455f-8929-273f93c7ca68:8e0f3a0ae39d498581ed51417dbe65ec
[I 17:45:38.916 NotebookApp] Kernel shutdown: b08c12d5-ff07-455f-8929-273f93c7ca68
[E 17:45:38.917 NotebookApp] Uncaught exception DELETE /api/sessions/2bed0f83-9232-4276-a97e-50c3417bd41e (127.0.0.1)
    HTTPServerRequest(protocol='http', host='localhost:8888', method='DELETE', uri='/api/sessions/2bed0f83-9232-4276-a97e-50c3417bd41e', version='HTTP/1.1', remote_ip='127.0.0.1')
    Traceback (most recent call last):
      File "/home/gang/anaconda3/envs/ETRI/lib/python3.9/site-packages/tornado/web.py", line 1713, in _execute
        result = await result
      File "/home/gang/anaconda3/envs/ETRI/lib/python3.9/site-packages/tornado/gen.py", line 776, in run
        yielded = self.gen.throw(*exc_info)  # type: ignore
      File "/home/gang/anaconda3/envs/ETRI/lib/python3.9/site-packages/notebook/services/sessions/handlers.py", line 164, in delete
        yield maybe_future(sm.delete_session(session_id))
      File "/home/gang/anaconda3/envs/ETRI/lib/python3.9/site-packages/tornado/gen.py", line 769, in run
        value = future.result()
      File "/home/gang/anaconda3/envs/ETRI/lib/python3.9/site-packages/tornado/gen.py", line 782, in run
        yielded = self.gen.send(value)
      File "/home/gang/anaconda3/envs/ETRI/lib/python3.9/site-packages/notebook/services/sessions/sessionmanager.py", line 287, in delete_session
        yield maybe_future(self.kernel_manager.shutdown_kernel(session['kernel']['id']))
      File "/home/gang/anaconda3/envs/ETRI/lib/python3.9/site-packages/notebook/services/kernels/kernelmanager.py", line 304, in shutdown_kernel
        self.pinned_superclass.shutdown_kernel(self, kernel_id, now=now, restart=restart)
      File "/home/gang/anaconda3/envs/ETRI/lib/python3.9/site-packages/jupyter_client/utils.py", line 30, in wrapped
        raise e
      File "/home/gang/anaconda3/envs/ETRI/lib/python3.9/site-packages/jupyter_client/utils.py", line 27, in wrapped
        return loop.run_until_complete(future)
      File "/home/gang/anaconda3/envs/ETRI/lib/python3.9/site-packages/nest_asyncio.py", line 90, in run_until_complete
        return f.result()
      File "/home/gang/anaconda3/envs/ETRI/lib/python3.9/asyncio/futures.py", line 201, in result
        raise self._exception
      File "/home/gang/anaconda3/envs/ETRI/lib/python3.9/asyncio/tasks.py", line 256, in __step
        result = coro.send(None)
      File "/home/gang/anaconda3/envs/ETRI/lib/python3.9/site-packages/jupyter_client/multikernelmanager.py", line 264, in _async_shutdown_kernel
        if not km.ready.cancelled() and km.ready.exception():
    asyncio.exceptions.InvalidStateError: Exception is not set.
[W 17:45:38.918 NotebookApp] Unhandled error
[E 17:45:38.918 NotebookApp] {
      "Host": "localhost:8888",
      "Accept": "application/json, text/javascript, */*; q=0.01",
      "Referer": "http://localhost:8888/notebooks/Untitled.ipynb?kernel_name=python3",
      "User-Agent": "Mozilla/5.0 (X11; Linux x86_64) AppleWebKit/537.36 (KHTML, like Gecko) Chrome/110.0.0.0 Safari/537.36"
    }
[E 17:45:38.918 NotebookApp] 500 DELETE /api/sessions/2bed0f83-9232-4276-a97e-50c3417bd41e (127.0.0.1) 2.130000ms referer=http://localhost:8888/notebooks/Untitled.ipynb?kernel_name=python3
[I 17:45:39.071 NotebookApp] Kernel shutdown: aeceefd9-a79b-475e-805a-ae88dfaec4bd
[I 17:45:39.121 NotebookApp] Starting buffering for aeceefd9-a79b-475e-805a-ae88dfaec4bd:1352a919f06f4b2cba0d4055ef729a98
[I 17:45:39.124 NotebookApp] Kernel shutdown: aeceefd9-a79b-475e-805a-ae88dfaec4bd
[E 17:45:39.124 NotebookApp] Uncaught exception DELETE /api/sessions/c87bb8fa-b31a-4f92-82bd-ac8d07e4cb10 (127.0.0.1)
    HTTPServerRequest(protocol='http', host='localhost:8888', method='DELETE', uri='/api/sessions/c87bb8fa-b31a-4f92-82bd-ac8d07e4cb10', version='HTTP/1.1', remote_ip='127.0.0.1')
    Traceback (most recent call last):
      File "/home/gang/anaconda3/envs/ETRI/lib/python3.9/site-packages/tornado/web.py", line 1713, in _execute
        result = await result
      File "/home/gang/anaconda3/envs/ETRI/lib/python3.9/site-packages/tornado/gen.py", line 776, in run
        yielded = self.gen.throw(*exc_info)  # type: ignore
      File "/home/gang/anaconda3/envs/ETRI/lib/python3.9/site-packages/notebook/services/sessions/handlers.py", line 164, in delete
        yield maybe_future(sm.delete_session(session_id))
      File "/home/gang/anaconda3/envs/ETRI/lib/python3.9/site-packages/tornado/gen.py", line 769, in run
        value = future.result()
      File "/home/gang/anaconda3/envs/ETRI/lib/python3.9/site-packages/tornado/gen.py", line 782, in run
        yielded = self.gen.send(value)
      File "/home/gang/anaconda3/envs/ETRI/lib/python3.9/site-packages/notebook/services/sessions/sessionmanager.py", line 287, in delete_session
        yield maybe_future(self.kernel_manager.shutdown_kernel(session['kernel']['id']))
      File "/home/gang/anaconda3/envs/ETRI/lib/python3.9/site-packages/notebook/services/kernels/kernelmanager.py", line 304, in shutdown_kernel
        self.pinned_superclass.shutdown_kernel(self, kernel_id, now=now, restart=restart)
      File "/home/gang/anaconda3/envs/ETRI/lib/python3.9/site-packages/jupyter_client/utils.py", line 30, in wrapped
        raise e
      File "/home/gang/anaconda3/envs/ETRI/lib/python3.9/site-packages/jupyter_client/utils.py", line 27, in wrapped
        return loop.run_until_complete(future)
      File "/home/gang/anaconda3/envs/ETRI/lib/python3.9/site-packages/nest_asyncio.py", line 90, in run_until_complete
        return f.result()
      File "/home/gang/anaconda3/envs/ETRI/lib/python3.9/asyncio/futures.py", line 201, in result
        raise self._exception
      File "/home/gang/anaconda3/envs/ETRI/lib/python3.9/asyncio/tasks.py", line 256, in __step
        result = coro.send(None)
      File "/home/gang/anaconda3/envs/ETRI/lib/python3.9/site-packages/jupyter_client/multikernelmanager.py", line 264, in _async_shutdown_kernel
        if not km.ready.cancelled() and km.ready.exception():
    asyncio.exceptions.InvalidStateError: Exception is not set.
[W 17:45:39.124 NotebookApp] Unhandled error
[E 17:45:39.124 NotebookApp] {
      "Host": "localhost:8888",
      "Accept": "application/json, text/javascript, */*; q=0.01",
      "Referer": "http://localhost:8888/notebooks/EDA_gang.ipynb",
      "User-Agent": "Mozilla/5.0 (X11; Linux x86_64) AppleWebKit/537.36 (KHTML, like Gecko) Chrome/110.0.0.0 Safari/537.36"
    }
[E 17:45:39.124 NotebookApp] 500 DELETE /api/sessions/c87bb8fa-b31a-4f92-82bd-ac8d07e4cb10 (127.0.0.1) 1.350000ms referer=http://localhost:8888/notebooks/EDA_gang.ipynb
[I 17:45:39.183 NotebookApp] Shutting down 0 terminals
[W 18:01:28.276 NotebookApp] Loading JupyterLab as a classic notebook (v6) extension.
[I 2023-03-18 18:01:28.279 LabApp] JupyterLab extension loaded from /home/gang/anaconda3/envs/ETRI/lib/python3.9/site-packages/jupyterlab
[I 2023-03-18 18:01:28.279 LabApp] JupyterLab application directory is /home/gang/anaconda3/envs/ETRI/share/jupyter/lab
[I 18:01:28.750 NotebookApp] Serving notebooks from local directory: /home/gang/PycharmProjects/ETRI2023
[I 18:01:28.750 NotebookApp] Jupyter Notebook 6.5.2 is running at:
[I 18:01:28.750 NotebookApp] http://localhost:8888/?token=3942073e6f33c7c0ed0fcc85c35ad638a796d6f58edcfe67
[I 18:01:28.750 NotebookApp]  or http://127.0.0.1:8888/?token=3942073e6f33c7c0ed0fcc85c35ad638a796d6f58edcfe67
[I 18:01:28.750 NotebookApp] Use Control-C to stop this server and shut down all kernels (twice to skip confirmation).
[C 18:01:28.764 NotebookApp] 
    
    To access the notebook, open this file in a browser:
        file:///home/gang/.local/share/jupyter/runtime/nbserver-703178-open.html
    Or copy and paste one of these URLs:
        http://localhost:8888/?token=3942073e6f33c7c0ed0fcc85c35ad638a796d6f58edcfe67
     or http://127.0.0.1:8888/?token=3942073e6f33c7c0ed0fcc85c35ad638a796d6f58edcfe67
[W 18:01:36.579 NotebookApp] Notebook Untitled.ipynb is not trusted
[I 18:01:36.686 NotebookApp] Kernel started: 84bfb548-8a76-4270-a7e2-41390de7bd28, name: python3
[I 18:03:36.672 NotebookApp] Saving file at /Untitled.ipynb
/home/gang/anaconda3/envs/ETRI/lib/python3.9/site-packages/nbformat/__init__.py:128: MissingIDFieldWarning: Code cell is missing an id field, this will become a hard error in future nbformat versions. You may want to use `normalize()` on your notebooks before validations (available since nbformat 5.1.4). Previous versions of nbformat are fixing this issue transparently, and will stop doing so in the future.
  validate(nb)
/home/gang/anaconda3/envs/ETRI/lib/python3.9/site-packages/notebook/services/contents/manager.py:353: MissingIDFieldWarning: Code cell is missing an id field, this will become a hard error in future nbformat versions. You may want to use `normalize()` on your notebooks before validations (available since nbformat 5.1.4). Previous versions of nbformat are fixing this issue transparently, and will stop doing so in the future.
  validate_nb(model['content'])
[I 18:05:36.664 NotebookApp] Saving file at /Untitled.ipynb
[I 18:07:36.663 NotebookApp] Saving file at /Untitled.ipynb
[I 18:09:36.672 NotebookApp] Saving file at /Untitled.ipynb
[I 18:11:36.663 NotebookApp] Saving file at /Untitled.ipynb
[I 18:13:36.670 NotebookApp] Saving file at /Untitled.ipynb
[I 18:13:58.315 NotebookApp] Saving file at /Untitled.ipynb
[C 18:29:15.615 NotebookApp] received signal 15, stopping
[I 18:29:15.615 NotebookApp] Shutting down 1 kernel
[I 18:29:15.616 NotebookApp] Kernel shutdown: 84bfb548-8a76-4270-a7e2-41390de7bd28
[I 18:29:15.674 NotebookApp] Starting buffering for 84bfb548-8a76-4270-a7e2-41390de7bd28:12e0d773292e4331ac1b197bf30e379e
[I 18:29:15.676 NotebookApp] Kernel shutdown: 84bfb548-8a76-4270-a7e2-41390de7bd28
[E 18:29:15.676 NotebookApp] Uncaught exception DELETE /api/sessions/79f5c8c5-60f5-4c5a-9cfa-8696995320b6 (127.0.0.1)
    HTTPServerRequest(protocol='http', host='localhost:8888', method='DELETE', uri='/api/sessions/79f5c8c5-60f5-4c5a-9cfa-8696995320b6', version='HTTP/1.1', remote_ip='127.0.0.1')
    Traceback (most recent call last):
      File "/home/gang/anaconda3/envs/ETRI/lib/python3.9/site-packages/tornado/web.py", line 1713, in _execute
        result = await result
      File "/home/gang/anaconda3/envs/ETRI/lib/python3.9/site-packages/tornado/gen.py", line 776, in run
        yielded = self.gen.throw(*exc_info)  # type: ignore
      File "/home/gang/anaconda3/envs/ETRI/lib/python3.9/site-packages/notebook/services/sessions/handlers.py", line 164, in delete
        yield maybe_future(sm.delete_session(session_id))
      File "/home/gang/anaconda3/envs/ETRI/lib/python3.9/site-packages/tornado/gen.py", line 769, in run
        value = future.result()
      File "/home/gang/anaconda3/envs/ETRI/lib/python3.9/site-packages/tornado/gen.py", line 782, in run
        yielded = self.gen.send(value)
      File "/home/gang/anaconda3/envs/ETRI/lib/python3.9/site-packages/notebook/services/sessions/sessionmanager.py", line 287, in delete_session
        yield maybe_future(self.kernel_manager.shutdown_kernel(session['kernel']['id']))
      File "/home/gang/anaconda3/envs/ETRI/lib/python3.9/site-packages/notebook/services/kernels/kernelmanager.py", line 304, in shutdown_kernel
        self.pinned_superclass.shutdown_kernel(self, kernel_id, now=now, restart=restart)
      File "/home/gang/anaconda3/envs/ETRI/lib/python3.9/site-packages/jupyter_client/utils.py", line 30, in wrapped
        raise e
      File "/home/gang/anaconda3/envs/ETRI/lib/python3.9/site-packages/jupyter_client/utils.py", line 27, in wrapped
        return loop.run_until_complete(future)
      File "/home/gang/anaconda3/envs/ETRI/lib/python3.9/site-packages/nest_asyncio.py", line 90, in run_until_complete
        return f.result()
      File "/home/gang/anaconda3/envs/ETRI/lib/python3.9/asyncio/futures.py", line 201, in result
        raise self._exception
      File "/home/gang/anaconda3/envs/ETRI/lib/python3.9/asyncio/tasks.py", line 256, in __step
        result = coro.send(None)
      File "/home/gang/anaconda3/envs/ETRI/lib/python3.9/site-packages/jupyter_client/multikernelmanager.py", line 264, in _async_shutdown_kernel
        if not km.ready.cancelled() and km.ready.exception():
    asyncio.exceptions.InvalidStateError: Exception is not set.
[W 18:29:15.677 NotebookApp] Unhandled error
[E 18:29:15.677 NotebookApp] {
      "Host": "localhost:8888",
      "Accept": "application/json, text/javascript, */*; q=0.01",
      "Referer": "http://localhost:8888/notebooks/Untitled.ipynb",
      "User-Agent": "Mozilla/5.0 (X11; Linux x86_64) AppleWebKit/537.36 (KHTML, like Gecko) Chrome/110.0.0.0 Safari/537.36"
    }
[E 18:29:15.677 NotebookApp] 500 DELETE /api/sessions/79f5c8c5-60f5-4c5a-9cfa-8696995320b6 (127.0.0.1) 2.250000ms referer=http://localhost:8888/notebooks/Untitled.ipynb
[I 18:29:15.828 NotebookApp] Shutting down 0 terminals
